<robot
  name="waiterbot_description">
  <link name="base_footprint"/>
    <joint name="base_joint" type="fixed">
      <origin xyz="0 0 0.0102" rpy="0 0 0" />
      <parent link="base_footprint"/>
      <child link="base_link" />
    </joint>
  <link
    name="base_link">
    <inertial>
      <origin
        xyz="-0.0996669957747876 1.45131214129999E-05 0.354341697716168"
        rpy="0 0 0" />
      <mass
        value="80.1722695309394" />
      <inertia
        ixx="4.45627593650221"
        ixy="-0.000120784019756137"
        ixz="-0.0663886125014259"
        iyy="4.45433930232212"
        iyz="0.000402253446569661"
        izz="1.47601648850678" />
    </inertial>
    <visual>
      <origin
        xyz="0 0 0"
        rpy="0 0 0" />
      <geometry>
        <mesh
          filename="package://waiterbot_description/meshes/base_link.STL" />
      </geometry>
      <material
        name="">
        <color
          rgba="0.117647058823529 0.658823529411765 1 1" />
      </material>
    </visual>
    <collision>
      <origin
        xyz="0 0 0"
        rpy="0 0 0" />
      <geometry>
        <mesh
          filename="package://waiterbot_description/meshes/base_link.STL" />
      </geometry>
    </collision>
  </link>
  <link
    name="left_wheel_Link">
    <inertial>
      <origin
        xyz="0 0 0"
        rpy="0 0 0" />
      <mass
        value="0.214252405612172" />
      <inertia
        ixx="0.000179109395223178"
        ixy="1.74518243681741E-11"
        ixz="3.57851021254128E-14"
        iyy="0.000301767221213604"
        iyz="7.9272265953424E-14"
        izz="0.000179081236639626" />
    </inertial>
    <visual>
      <origin
        xyz="0 0 0"
        rpy="0 0 0" />
      <geometry>
        <mesh
          filename="package://waiterbot_description/meshes/left_wheel_Link.STL" />
      </geometry>
      <material
        name="">
        <color
          rgba="1 1 1 1" />
      </material>
    </visual>
    <collision>
      <origin
        xyz="0 0 0"
        rpy="0 0 0" />
      <geometry>
        <mesh
          filename="package://waiterbot_description/meshes/left_wheel_Link.STL" />
      </geometry>
    </collision>
  </link>
  <joint
    name="left_wheel_joint"
    type="continuous">
    <origin
      xyz="0 0.147897664300195 0.0274999999693413"
      rpy="0 0 0" />
    <parent
      link="base_link" />
    <child
      link="left_wheel_Link" />
    <axis
      xyz="0 1 0" />
  </joint>
  <link
    name="right_wheel_Link">
    <inertial>
      <origin
        xyz="0 0 0"
        rpy="0 0 0" />
      <mass
        value="0.214252405507579" />
      <inertia
        ixx="0.000179109395198057"
        ixy="-1.75373762792168E-11"
        ixz="-1.0028090968596E-13"
        iyy="0.000301767221051853"
        iyz="6.65719731111029E-14"
        izz="0.000179081236452865" />
    </inertial>
    <visual>
      <origin
        xyz="0 0 0"
        rpy="0 0 0" />
      <geometry>
        <mesh
          filename="package://waiterbot_description/meshes/right_wheel_Link.STL" />
      </geometry>
      <material
        name="">
        <color
          rgba="1 1 1 1" />
      </material>
    </visual>
    <collision>
      <origin
        xyz="0 0 0"
        rpy="0 0 0" />
      <geometry>
        <mesh
          filename="package://waiterbot_description/meshes/right_wheel_Link.STL" />
      </geometry>
    </collision>
  </link>
  <joint
    name="right_wheel_joint"
    type="continuous">
    <origin
      xyz="0 -0.147897664300856 0.0275000000281899"
      rpy="0 0 0" />
    <parent
      link="base_link" />
    <child
      link="right_wheel_Link" />
    <axis
      xyz="0 1 0" />
  </joint>
  <link
    name="omni_wheel_Link">
    <inertial>
      <origin
        xyz="0 6.51512757319569E-20 0"
        rpy="0 0 0" />
      <mass
        value="0.00634815361064737" />
      <inertia
        ixx="3.35342847845056E-07"
        ixy="-2.04764363484238E-18"
        ixz="2.08969324119687E-21"
        iyy="4.93529263557337E-07"
        iyz="1.0919258939827E-15"
        izz="3.35312650108157E-07" />
    </inertial>
    <visual>
      <origin
        xyz="0 0 0"
        rpy="0 0 0" />
      <geometry>
        <mesh
          filename="package://waiterbot_description/meshes/omni_wheel_Link.STL" />
      </geometry>
      <material
        name="">
        <color
          rgba="1 0.807843137254902 0.458823529411765 1" />
      </material>
    </visual>
    <collision>
      <origin
        xyz="0 0 0"
        rpy="0 0 0" />
      <geometry>
        <mesh
          filename="package://waiterbot_description/meshes/omni_wheel_Link.STL" />
      </geometry>
    </collision>
  </link>
  <joint
    name="omni_wheel_joint"
    type="fixed">
    <origin
      xyz="-0.260000004749928 0 -0.0100000000089026"
      rpy="0 0 0" />
    <parent
      link="base_link" />
    <child
      link="omni_wheel_Link" />
    <axis
      xyz="0 0 0" />
  </joint>
  <!--link
    name="kinect2_link">
    <inertial>
      <origin
        xyz="5.00413110110391E-05 0.143804354117406 0.112167590252249"
        rpy="0 0 0" />
      <mass
        value="0.819847601278127" />
      <inertia
        ixx="0.00058543011881325"
        ixy="-3.87035163303318E-07"
        ixz="-3.91817878812889E-09"
        iyy="0.00432193908675339"
        iyz="2.63136905263757E-05"
        izz="0.00416131242714742" />
    </inertial>
    <visual>
      <origin
        xyz="0 0 0"
        rpy="0 0 0" />
      <geometry>
        <mesh
          filename="package://waiterbot_description/meshes/kinect2_link.STL" />
      </geometry>
      <material
        name="">
        <color
          rgba="0.549019607843137 0.219607843137255 0.109803921568627 1" />
      </material>
    </visual>
    <collision>
      <origin
        xyz="0 0 0"
        rpy="0 0 0" />
      <geometry>
        <mesh
          filename="package://waiterbot_description/meshes/kinect2_link.STL" />
      </geometry>
    </collision>
  </link>
  <joint
    name="kinect2_joint"
    type="fixed">
    <origin
      xyz="-0.1 0 0.12"
      rpy="1.5707963267949 0 1.5707963267949" />
    <parent
      link="base_link" />
    <child
      link="kinect2_link" />
    <axis
      xyz="0 0 0" />
  </joint-->

  <!--link
    name="camera_link">
    <inertial>
      <origin
        xyz="1.3878E-17 1.1102E-16 -0.00026767"
        rpy="0 0 0" />
      <mass
        value="0.154" />
      <inertia
        ixx="2.4237E-05"
        ixy="-9.6537E-22"
        ixz="-8.3256E-21"
        iyy="0.00041068"
        iyz="-2.6916E-22"
        izz="0.00040212" />
    </inertial>
    <visual>
      <origin
        xyz="0 0 0"
        rpy="1.5708 0 1.5708" />
      <geometry>
        <mesh
          filename="package://water_description/meshes/camera_link.stl" />
      </geometry>
      <material
        name="">
        <color
          rgba="0.2 0.2 0.2 1" />
      </material>
    </visual>
    <collision>
      <origin
        xyz="0 0 0"
        rpy="0 0 0" />
      <geometry>
        <mesh
          filename="package://water_description/meshes/camera_link.stl" />
      </geometry>
    </collision>
  </link>
  <joint
    name="camera_joint"
    type="fixed">
    <origin
      xyz="0.0121675902522488 5.0041311011069E-05 0.263804354117406"
      rpy="0 -4.482E-31 0" />
    <parent
      link="base_link" />
    <child
      link="camera_link" />
    <axis
      xyz="0 0 0" />
  </joint-->
  <!--for camera sensor model -->
      <!--joint name="camera_depth_joint" type="fixed">
        <origin xyz="0.0 0.049 0.0" rpy="0 0 0" />
        <parent link="camera_link" />
        <child link="camera_depth_frame"/>
      </joint>
      <link name="camera_depth_frame"/>

      <joint name="camera_depth_optical_joint" type="fixed">
        <origin xyz="0 0 0" rpy="-1.5708 0.0 -1.5708" />
        <parent link="camera_depth_frame" />
        <child link="camera_depth_optical_frame"/>
      </joint>

      <link name="camera_depth_optical_frame"/>

      <joint name="camera_rgb_joint" type="fixed">
        <origin xyz="0.0 0.022 0.0" rpy="0 0 0" />
        <parent link="camera_link" />
        <child link="camera_rgb_frame"/>
      </joint>

      <link name="camera_rgb_frame"/>

      <joint name="camera_rgb_optical_joint" type="fixed">
        <origin xyz="0 0 0" rpy="-1.5708 0.0 -1.5708" />
        <parent link="camera_rgb_frame" />
        <child link="camera_rgb_optical_frame"/>
      </joint>
      <link name="camera_rgb_optical_frame"/-->
</robot>
